<mujoco model="MyoElbow_v0.1.7">
  <!-- =================================================
    Copyright 2020 Vikash Kumar, Vittorio Caggiano, Huawei Wang
    Model   :: Myo Hand (MuJoCoV2.0)
    Author  :: Vikash Kumar (vikashplus@gmail.com), Vittorio Caggiano, Huawei Wang
    source  :: https://github.com/vikashplus
    License :: Under Apache License, Version 2.0 (the "License"); you may not use this file except in compliance with the License. You may obtain a copy of the License at http://www.apache.org/licenses/LICENSE-2.0 Unless required by applicable law or agreed to in writing, software distributed under the License is distributed on an "AS IS" BASIS, WITHOUT WARRANTIES OR CONDITIONS OF ANY KIND, either express or implied. See the License for the specific language governing permissions and limitations under the License.
====================================================== -->
  <compiler angle="radian" meshdir="../" texturedir="../" boundmass="0.001" boundinertia="0.001"/>

  <size njmax="1000" nconmax="400" nuser_jnt="1"/>

  <visual>
    <headlight diffuse="1 1 1"/>
    <scale actuatorwidth="0.075"/>
  </visual>

  <default>
    <default class="myoElbow">
      <joint limited="true" armature="0.01" damping="0.5"/>
      <geom conaffinity="0" solimp="0.8 0.8 0.01" margin="0.001" material="geom" rgba="0.8 0.85 0.8 1"/>
      <site size="0.001 0.005 0.005"/>

      <tendon limited="false" width="0.005" rgba="0.95 0.3 0.3 1"/>
      <default class="muscle">
        <general ctrllimited="true" ctrlrange="0.001 1" dyntype="muscle" dynprm="0.01 0.04 0 0 0 0 0 0 0 0" gaintype="muscle" biastype="muscle" gainprm="0.75 1.05 -1 1 0.5 1.6 15 1.3 1.4" biasprm="0.75 1.05 -1 1 0.5 1.6 15 1.3 1.4"/>
      </default>
    </default>
  </default>

  <asset>
    <texture type="2d" name="texplane" builtin="checker" rgb1="0.2 0.19 0.2" rgb2="0.1 0.11 0.11" width="50" height="50"/>
    <texture type="cube" name="texgeom" builtin="flat" mark="cross" rgb1="0.7 0.7 0.7" rgb2="0.9 0.9 0.9" markrgb="1 1 1" width="127" height="762"/>
    <material name="MatPlane" texture="texplane" texuniform="true" texrepeat="4 4" reflectance="0.5"/>
    <material name="geom" texture="texgeom" texuniform="true"/>
    <mesh name="body_norighthand" file="../myo_sim/meshes/human_lowpoly_norighthand.stl"/>
    <mesh name="ground_ribs" file="../myo_sim/meshes/thorax.stl"/>
    <mesh name="ground_spine" file="../myo_sim/meshes/ground_spine.stl"/>
    <mesh name="ground_skull" file="../myo_sim/meshes/ground_skull.stl"/>
    <mesh name="ground_jaw" file="../myo_sim/meshes/ground_jaw.stl"/>
    <mesh name="ground_r_clavicle" file="../myo_sim/meshes/ground_r_clavicle.stl"/>
    <mesh name="ground_r_scapula" file="../myo_sim/meshes/ground_r_scapula.stl"/>
    <mesh name="arm_r_humerus" file="../myo_sim/meshes/arm_r_humerus.stl"/>
    <mesh name="arm_r_ulna" file="../myo_sim/meshes/arm_r_ulna.stl"/>
    <mesh name="arm_r_radius" file="../myo_sim/meshes/arm_r_radius.stl"/>
    <mesh name="arm_r_lunate" file="../myo_sim/meshes/arm_r_lunate.stl"/>
    <mesh name="arm_r_scaphoid" file="../myo_sim/meshes/arm_r_scaphoid.stl"/>
    <mesh name="arm_r_pisiform" file="../myo_sim/meshes/arm_r_pisiform.stl"/>
    <mesh name="arm_r_triquetrum" file="../myo_sim/meshes/arm_r_triquetrum.stl"/>
    <mesh name="arm_r_capitate" file="../myo_sim/meshes/arm_r_capitate.stl"/>
    <mesh name="arm_r_trapezium" file="../myo_sim/meshes/arm_r_trapezium.stl"/>
    <mesh name="arm_r_trapezoid" file="../myo_sim/meshes/arm_r_trapezoid.stl"/>
    <mesh name="arm_r_hamate" file="../myo_sim/meshes/arm_r_hamate.stl"/>
    <mesh name="arm_r_1mc" file="../myo_sim/meshes/arm_r_1mc.stl"/>
    <mesh name="arm_r_2mc" file="../myo_sim/meshes/arm_r_2mc.stl"/>
    <mesh name="arm_r_3mc" file="../myo_sim/meshes/arm_r_3mc.stl"/>
    <mesh name="arm_r_4mc" file="../myo_sim/meshes/arm_r_4mc.stl"/>
    <mesh name="arm_r_5mc" file="../myo_sim/meshes/arm_r_5mc.stl"/>
    <mesh name="arm_r_thumbprox" file="../myo_sim/meshes/arm_r_thumbprox.stl"/>
    <mesh name="arm_r_thumbdist" file="../myo_sim/meshes/arm_r_thumbdist.stl"/>
    <mesh name="arm_r_2proxph" file="../myo_sim/meshes/arm_r_2proxph.stl"/>
    <mesh name="arm_r_2midph" file="../myo_sim/meshes/arm_r_2midph.stl"/>
    <mesh name="arm_r_2distph" file="../myo_sim/meshes/arm_r_2distph.stl"/>
    <mesh name="arm_r_3proxph" file="../myo_sim/meshes/arm_r_3proxph.stl"/>
    <mesh name="arm_r_3midph" file="../myo_sim/meshes/arm_r_3midph.stl"/>
    <mesh name="arm_r_3distph" file="../myo_sim/meshes/arm_r_3distph.stl"/>
    <mesh name="arm_r_4proxph" file="../myo_sim/meshes/arm_r_4proxph.stl"/>
    <mesh name="arm_r_4midph" file="../myo_sim/meshes/arm_r_4midph.stl"/>
    <mesh name="arm_r_4distph" file="../myo_sim/meshes/arm_r_4distph.stl"/>
    <mesh name="arm_r_5proxph" file="../myo_sim/meshes/arm_r_5proxph.stl"/>
    <mesh name="arm_r_5midph" file="../myo_sim/meshes/arm_r_5midph.stl"/>
    <mesh name="arm_r_5distph" file="../myo_sim/meshes/arm_r_5distph.stl"/>
  </asset>

  <worldbody>
    <body name="full_body" childclass="myoElbow">
      <body name="base" pos="0 0 0.8" quat="0.707035 0.707179 0 0">
        <site name="TRIlong-P1" pos="-0.0536 -0.0137 0.1472"/>
        <site name="BIClong-P1" pos="-0.0392 0.0035 0.148"/>
        <site name="BIClong-P2" pos="-0.0289 0.0139 0.1564"/>
        <site name="BICshort-P1" pos="0.0047 -0.0123 0.1348"/>
        <site name="BICshort-P2" pos="-0.0071 -0.04 0.1451"/>
        <body name="r_humerus" pos="-0.017545 -0.007 0.17">
          <inertial pos="0 -0.180496 0" quat="0.707107 0.707107 0 0" mass="1.86457" diaginertia="0.01481 0.013193 0.004551"/>
          <joint name="r_shoulder_elev" pos="0 0 0" axis="-0.058898 0.0023 0.998261" range="-1.5708 3.14159"/>
          <geom name="arm_r_humerus" type="mesh" mesh="arm_r_humerus"/>
          <geom name="TRIlonghh_wrap" size="0.03" pos="0.0068 0 0.0034" quat="0.4142 0.226399 -0.879896 -0.0544578" group="2" rgba="0.5 0.5 0.9 0.4"/>
          <geom name="BIClonghh_wrap" size="0.025" pos="-0.001 -0.0008 0.0012" group="2" rgba="0.5 0.5 0.9 0.4"/>
          <geom name="TRI_wrap" size="0.016 0.025" pos="0.0028 -0.2919 -0.0069" quat="0.99453 -0.0700498 0.00229591 0.0774439" type="cylinder" group="2" rgba="0.5 0.5 0.9 0.4"/>
          <site name="TRIlong-P2" pos="-0.0271 -0.1144 -0.0066"/>
          <site name="TRIlong-P3" pos="-0.0318 -0.2264 -0.0122"/>
          <site name="TRIlong-P4" pos="-0.0174 -0.2676 -0.0121"/>
          <site name="TRIlat-P1" pos="-0.006 -0.1265 0.0043"/>
          <site name="TRIlat-P2" pos="-0.0234 -0.1453 0.0093"/>
          <site name="TRIlat-P3" pos="-0.0318 -0.2264 -0.0122"/>
          <site name="TRIlat-P4" pos="-0.0174 -0.2676 -0.0121"/>
          <site name="TRImed-P1" pos="-0.0084 -0.1369 -0.0091"/>
          <site name="TRImed-P2" pos="-0.026 -0.1514 -0.0108"/>
          <site name="TRImed-P3" pos="-0.0318 -0.2264 -0.0122"/>
          <site name="TRImed-P4" pos="-0.0174 -0.2676 -0.0121"/>
          <site name="BIClong-P3" pos="0.0213 0.0179 0.0103"/>
          <site name="BIClong-P4" pos="0.0238 -0.0051 0.012"/>
          <site name="BIClong-P5" pos="0.0134 -0.0283 0.0014"/>
          <site name="BIClong-P6" pos="0.0107 -0.0774 -0.0016"/>
          <site name="BIClong-P7" pos="0.017 -0.1212 0.0002"/>
          <site name="BIClong-P8" pos="0.0228 -0.1754 -0.0063"/>
          <site name="BICshort-P3" pos="0.0112 -0.0758 -0.011"/>
          <site name="BICshort-P4" pos="0.017 -0.1212 -0.0108"/>
          <site name="BICshort-P5" pos="0.0228 -0.1754 -0.0063"/>
          <site name="BRA-P1" pos="0.0068 -0.1739 -0.0036"/>
          <site name="BIClonghh_site_BIClong_side" pos="0 0.03 -0.02"/>
          <site name="TRIlonghh_site_TRIlong_side" pos="-0.02 0 -0.035"/>
          <site name="TRI_site_TRIlong_side" pos="-0.0256308 -0.273692 0.0165713"/>
          <site name="TRI_site_TRIlat_side" pos="-0.0256308 -0.273692 0.0165713"/>
          <site name="TRI_site_TRImed_side" pos="-0.0289353 -0.297467 -0.0136312"/>
          <site name="TRI_site_BRA_side" pos="0.0188814 -0.25991 0.0179386"/>
          <body name="r_ulna_radius_hand" pos="0.0061 -0.2904 -0.0123">
            <inertial pos="0 -0.181479 0" quat="0.5 0.5 -0.5 0.5" mass="1.53432" diaginertia="0.020062 0.019281 0.001571"/>
            <joint name="r_elbow_flex" pos="0 0 0" axis="0.0494 0.0366 0.998108" range="0 2.26893"/>
            <geom name="arm_r_ulna" type="mesh" mesh="arm_r_ulna"/>
            <geom name="arm_r_radius" type="mesh" mesh="arm_r_radius"/>
            <geom name="arm_r_lunate" type="mesh" mesh="arm_r_lunate"/>
            <geom name="arm_r_scaphoid" type="mesh" mesh="arm_r_scaphoid"/>
            <geom name="arm_r_pisiform" type="mesh" mesh="arm_r_pisiform"/>
            <geom name="arm_r_triquetrum" type="mesh" mesh="arm_r_triquetrum"/>
            <geom name="arm_r_capitate" type="mesh" mesh="arm_r_capitate"/>
            <geom name="arm_r_trapezium" type="mesh" mesh="arm_r_trapezium"/>
            <geom name="arm_r_trapezoid" type="mesh" mesh="arm_r_trapezoid"/>
            <geom name="arm_r_hamate" type="mesh" mesh="arm_r_hamate"/>
            <geom name="arm_r_1mc" type="mesh" mesh="arm_r_1mc"/>
            <geom name="arm_r_2mc" type="mesh" mesh="arm_r_2mc"/>
            <geom name="arm_r_3mc" type="mesh" mesh="arm_r_3mc"/>
            <geom name="arm_r_4mc" type="mesh" mesh="arm_r_4mc"/>
            <geom name="arm_r_5mc" type="mesh" mesh="arm_r_5mc"/>
            <geom name="arm_r_thumbprox" type="mesh" mesh="arm_r_thumbprox"/>
            <geom name="arm_r_thumbdist" type="mesh" mesh="arm_r_thumbdist"/>
            <geom name="arm_r_2proxph" type="mesh" mesh="arm_r_2proxph"/>
            <geom name="arm_r_2midph" type="mesh" mesh="arm_r_2midph"/>
            <geom name="arm_r_2distph" type="mesh" mesh="arm_r_2distph"/>
            <geom name="arm_r_3proxph" type="mesh" mesh="arm_r_3proxph"/>
            <geom name="arm_r_3midph" type="mesh" mesh="arm_r_3midph"/>
            <geom name="arm_r_3distph" type="mesh" mesh="arm_r_3distph"/>
            <geom name="arm_r_4proxph" type="mesh" mesh="arm_r_4proxph"/>
            <geom name="arm_r_4midph" type="mesh" mesh="arm_r_4midph"/>
            <geom name="arm_r_4distph" type="mesh" mesh="arm_r_4distph"/>
            <geom name="arm_r_5proxph" type="mesh" mesh="arm_r_5proxph"/>
            <geom name="arm_r_5midph" type="mesh" mesh="arm_r_5midph"/>
            <geom name="arm_r_5distph" type="mesh" mesh="arm_r_5distph"/>
            <site name="TRIlong-P5" pos="-0.0219 0.0105 -0.0008"/>
            <site name="TRIlat-P5" pos="-0.0219 0.0105 -0.0008"/>
            <site name="TRImed-P5" pos="-0.0219 0.0105 -0.0008"/>
            <site name="BIClong-P9" pos="0.0075 -0.0484 0.0218"/>
            <site name="BICshort-P6" pos="0.0075 -0.0484 0.0218"/>
            <site name="BRA-P2" pos="-0.0032 -0.0239 0.0009"/>
            <site name="wrist" pos="0.007 -0.261 0.065" size="0.005"/>
          </body>
        </body>
      </body>
    </body>
  </worldbody>

  <tendon>
    <spatial name="TRIlong_tendon" springlength="0.143">
      <site site="TRIlong-P1"/>
      <geom geom="TRIlonghh_wrap" sidesite="TRIlonghh_site_TRIlong_side"/>
      <site site="TRIlong-P2"/>
      <site site="TRIlong-P3"/>
      <site site="TRIlong-P4"/>
      <geom geom="TRI_wrap" sidesite="TRI_site_TRIlong_side"/>
      <site site="TRIlong-P5"/>
    </spatial>
    <spatial name="TRIlat_tendon" springlength="0.098">
      <site site="TRIlat-P1"/>
      <site site="TRIlat-P2"/>
      <site site="TRIlat-P3"/>
      <site site="TRIlat-P4"/>
      <geom geom="TRI_wrap" sidesite="TRI_site_TRIlat_side"/>
      <site site="TRIlat-P5"/>
    </spatial>
    <spatial name="TRImed_tendon" springlength="0.0908">
      <site site="TRImed-P1"/>
      <site site="TRImed-P2"/>
      <site site="TRImed-P3"/>
      <site site="TRImed-P4"/>
      <geom geom="TRI_wrap" sidesite="TRI_site_TRImed_side"/>
      <site site="TRImed-P5"/>
    </spatial>
    <spatial name="BIClong_tendon" springlength="0.2723">
      <site site="BIClong-P1"/>
      <site site="BIClong-P2"/>
      <geom geom="BIClonghh_wrap" sidesite="BIClonghh_site_BIClong_side"/>
      <site site="BIClong-P3"/>
      <site site="BIClong-P4"/>
      <site site="BIClong-P5"/>
      <site site="BIClong-P6"/>
      <site site="BIClong-P7"/>
      <site site="BIClong-P8"/>
      <site site="BIClong-P9"/>
    </spatial>
    <spatial name="BICshort_tendon" springlength="0.1923">
      <site site="BICshort-P1"/>
      <site site="BICshort-P2"/>
      <site site="BICshort-P3"/>
      <site site="BICshort-P4"/>
      <site site="BICshort-P5"/>
      <site site="BICshort-P6"/>
    </spatial>
    <spatial name="BRA_tendon" springlength="0.0535">
      <site site="BRA-P1"/>
      <geom geom="TRI_wrap" sidesite="TRI_site_BRA_side"/>
      <site site="BRA-P2"/>
    </spatial>
  </tendon>

  <actuator>
    <general name="TRIlong" class="muscle" tendon="TRIlong_tendon" lengthrange="0.253995 0.355816" gainprm="0.828323 1.58818 769.595 1 0.420881 1.90307 15 1.37875" biasprm="0.828323 1.58818 769.595 1 0.420881 1.90307 15 1.37875"/>
    <general name="TRIlat" class="muscle" tendon="TRIlat_tendon" lengthrange="0.16661 0.215095" gainprm="0.602904 1.02895 604.403 1 0.335897 2.90142 15 1.79842" biasprm="0.602904 1.02895 604.403 1 0.335897 2.90142 15 1.79842"/>
    <general name="TRImed" class="muscle" tendon="TRImed_tendon" lengthrange="0.154238 0.202723" gainprm="0.557454 0.983503 604.231 1 0.337519 2.16009 15 1.31972" biasprm="0.557454 0.983503 604.231 1 0.337519 2.16009 15 1.31972"/>
    <general name="BIClong" class="muscle" tendon="BIClong_tendon" lengthrange="0.324209 0.450055" gainprm="0.448656 1.53634 607.75 1 0.429169 1.98717 15 1.30324" biasprm="0.448656 1.53634 607.75 1 0.429169 1.98717 15 1.30324"/>
    <general name="BICshort" class="muscle" tendon="BICshort_tendon" lengthrange="0.268259 0.408052" gainprm="0.575015 1.63325 423.688 1 0.397179 1.96649 15 1.42184" biasprm="0.575015 1.63325 423.688 1 0.397179 1.96649 15 1.42184"/>
    <general name="BRA" class="muscle" tendon="BRA_tendon" lengthrange="0.105975 0.147329" gainprm="0.611597 1.09358 976.169 1 0.357419 2.99986 15 1.97876" biasprm="0.611597 1.09358 976.169 1 0.357419 2.99986 15 1.97876"/>
  </actuator>
</mujoco>
